<?xml version='1.0' encoding='utf-8'?>
<robot name="Robot">
    <link name="isaac_zup_root" />
    <link name="robot_torso_link">
        <inertial>
            <origin xyz="0.040610506256968416 -0.04428824406417338 0.15232735840639008" rpy="0 0 0" />
            <mass value="3.4766230099551185" />
            <inertia ixx="0.04556755879204122" iyy="0.05012873896013437" izz="0.029046998553490355" ixy="0.00013634333507087952" iyz="-0.0001431936018525537" ixz="-2.17772042035041e-05" />
        </inertial>
        <visual name="robot_torso_link_visual">
            <origin xyz="0.03999999999999753 -0.20650000405311944 -0.8247999999999932" rpy="0 0 -1.5707963267948957" />
            <geometry>
                <mesh filename="meshes/robot_torso_link.stl" scale="0.001 0.001 0.001" />
            </geometry>
        </visual>
        <collision name="robot_torso_link_collision">
            <origin xyz="0.03999999999999753 -0.20650000405311944 -0.8247999999999932" rpy="0 0 -1.5707963267948957" />
            <geometry>
                <mesh filename="meshes/robot_torso_link.stl" scale="0.001 0.001 0.001" />
            </geometry>
        </collision>
    </link>
    <link name="robot_pelvis_link">
        <inertial>
            <origin xyz="1.907307843928129e-09 0.8221283725272435 -0.1605000000000951" rpy="0 0 0" />
            <mass value="0.4703666239440356" />
            <inertia ixx="0.0004950338258166186" iyy="0.0051455689188816735" izz="0.004655577203476379" ixy="-1.2414480207597884e-16" iyz="-4.9898332365055555e-17" ixz="-2.465814750775911e-16" />
        </inertial>
        <visual name="robot_pelvis_link_visual">
            <origin xyz="0 0 0" rpy="0 0 0" />
            <geometry>
                <mesh filename="meshes/robot_pelvis_link.stl" scale="0.001 0.001 0.001" />
            </geometry>
        </visual>
        <collision name="robot_pelvis_link_collision">
            <origin xyz="0 0 0" rpy="0 0 0" />
            <geometry>
                <mesh filename="meshes/robot_pelvis_link.stl" scale="0.001 0.001 0.001" />
            </geometry>
        </collision>
    </link>
    <link name="robot_l_hip_yaw_link">
        <inertial>
            <origin xyz="0.06170580963744272 4.0725723238210774e-09 0.06827606857409264" rpy="0 0 0" />
            <mass value="6.333603185323419" />
            <inertia ixx="0.02843678214079315" iyy="0.039819487774459095" izz="0.025134874646244865" ixy="3.3506530883187224e-12" iyz="4.739653114427256e-12" ixz="-0.010596038307325806" />
        </inertial>
        <visual name="robot_l_hip_yaw_link_visual">
            <origin xyz="0.0010000019072620959 4.05311087803284e-09 0.12129999999998944" rpy="0 0 -3.1415926535897922" />
            <geometry>
                <mesh filename="meshes/robot_l_hip_yaw_link.stl" scale="0.001 0.001 0.001" />
            </geometry>
        </visual>
        <collision name="robot_l_hip_yaw_link_collision">
            <origin xyz="0.0010000019072620959 4.05311087803284e-09 0.12129999999998944" rpy="0 0 -3.1415926535897922" />
            <geometry>
                <mesh filename="meshes/robot_l_hip_yaw_link.stl" scale="0.001 0.001 0.001" />
            </geometry>
        </collision>
    </link>
    <link name="robot_l_hip_pitch_link">
        <inertial>
            <origin xyz="-0.026961844630383532 -5.718654837863824e-05 -0.07266905837477283" rpy="0 0 0" />
            <mass value="2.4943200880759124" />
            <inertia ixx="0.005318665627016328" iyy="0.003522102440374625" izz="0.003180338974461794" ixy="-1.3011627608694454e-07" iyz="-3.3025731688285376e-07" ixz="-0.0001121184352927268" />
        </inertial>
        <visual name="robot_l_hip_pitch_link_visual">
            <origin xyz="0.0008000040530120778 -0.2573000000000127 -0.07500000166893413" rpy="-1.5707963267948846 1.5707963267948957 0" />
            <geometry>
                <mesh filename="meshes/robot_l_hip_pitch_link.stl" scale="0.001 0.001 0.001" />
            </geometry>
        </visual>
        <collision name="robot_l_hip_pitch_link_collision">
            <origin xyz="0.0008000040530120778 -0.2573000000000127 -0.07500000166893413" rpy="-1.5707963267948846 1.5707963267948957 0" />
            <geometry>
                <mesh filename="meshes/robot_l_hip_pitch_link.stl" scale="0.001 0.001 0.001" />
            </geometry>
        </collision>
    </link>
    <link name="robot_l_thigh_link">
        <inertial>
            <origin xyz="-0.013245029323110238 0.004137659780995229 0.2579314528909539" rpy="0 0 0" />
            <mass value="3.0917752218546957" />
            <inertia ixx="0.02883218865798365" iyy="0.02680266525524866" izz="0.0036078750210082194" ixy="-0.00010068883616658197" iyz="0.0021454171666641098" ixz="0.0010188574668206496" />
        </inertial>
        <visual name="robot_l_thigh_link_visual">
            <origin xyz="-0.006500003619415988 -0.0004999989936364812 -4.4971353929668115e-09" rpy="0 0 -3.1415926535897922" />
            <geometry>
                <mesh filename="meshes/robot_l_thigh_link.stl" scale="0.001 0.001 0.001" />
            </geometry>
        </visual>
        <collision name="robot_l_thigh_link_collision">
            <origin xyz="-0.006500003619415988 -0.0004999989936364812 -4.4971353929668115e-09" rpy="0 0 -3.1415926535897922" />
            <geometry>
                <mesh filename="meshes/robot_l_thigh_link.stl" scale="0.001 0.001 0.001" />
            </geometry>
        </collision>
    </link>
    <link name="robot_l_shank_link">
        <inertial>
            <origin xyz="1.0063314803687718e-09 -0.14999999550286447 -0.020887096844043624" rpy="0 0 0" />
            <mass value="0.8515894596853654" />
            <inertia ixx="0.00881783580739591" iyy="0.0001854586688501969" izz="0.008885909396953509" ixy="1.8041124150158794e-16" iyz="-3.122502256758253e-17" ixz="8.326672684688674e-17" />
        </inertial>
        <visual name="robot_l_shank_link_visual">
            <origin xyz="1.0063660482728664e-09 0.3000000044971418 0.0215000038578307" rpy="1.5707963267948748 1.5707963267948957 0" />
            <geometry>
                <mesh filename="meshes/robot_l_shank_link.stl" scale="0.001 0.001 0.001" />
            </geometry>
        </visual>
        <collision name="robot_l_shank_link_collision">
            <origin xyz="1.0063660482728664e-09 0.3000000044971418 0.0215000038578307" rpy="1.5707963267948748 1.5707963267948957 0" />
            <geometry>
                <mesh filename="meshes/robot_l_shank_link.stl" scale="0.001 0.001 0.001" />
            </geometry>
        </collision>
    </link>
    <link name="robot_l_ankle_link">
        <inertial>
            <origin xyz="0.0025101682576991104 -2.943557837626898e-06 0.02769320947693526" rpy="0 0 0" />
            <mass value="2.497542686119488" />
            <inertia ixx="0.0031700443782680526" iyy="0.0035459766740820464" izz="0.0053616412686150056" ixy="3.5193338254746465e-07" iyz="-5.0583123394759566e-08" ixz="8.715197442184935e-05" />
        </inertial>
        <visual name="robot_l_ankle_link_visual">
            <origin xyz="1.156405310862141e-05 0.5999409200000082 0.01851564809273647" rpy="1.5707963267949099 -1.5707963267948954 0" />
            <geometry>
                <mesh filename="meshes/robot_l_ankle_link.stl" scale="0.001 0.001 0.001" />
            </geometry>
        </visual>
        <collision name="robot_l_ankle_link_collision">
            <origin xyz="1.156405310862141e-05 0.5999409200000082 0.01851564809273647" rpy="1.5707963267949099 -1.5707963267948954 0" />
            <geometry>
                <mesh filename="meshes/robot_l_ankle_link.stl" scale="0.001 0.001 0.001" />
            </geometry>
        </collision>
    </link>
    <link name="robot_l_foot_link">
        <inertial>
            <origin xyz="2.1152892060172234e-09 0.021295075182204172 0.009743852524878563" rpy="0 0 0" />
            <mass value="2.78967156731517" />
            <inertia ixx="0.007113124123467429" iyy="0.007089530917847892" izz="0.005986516031780263" ixy="3.03213044949846e-11" iyz="0.0012082495505332316" ixz="-3.797835657071147e-11" />
        </inertial>
        <visual name="robot_l_foot_link_visual">
            <origin xyz="-0.009499998092736472 -0.07399999594689137 -0.6000000000000082" rpy="0 0 -3.1415926535897922" />
            <geometry>
                <mesh filename="meshes/robot_l_foot_link.stl" scale="0.001 0.001 0.001" />
            </geometry>
        </visual>
        <collision name="robot_l_foot_link_collision">
            <origin xyz="-0.009499998092736472 -0.07399999594689137 -0.6000000000000082" rpy="0 0 -3.1415926535897922" />
            <geometry>
                <mesh filename="meshes/robot_l_foot_link.stl" scale="0.001 0.001 0.001" />
            </geometry>
        </collision>
    </link>
    <link name="robot_r_hip_yaw_link">
        <inertial>
            <origin xyz="-0.06170580582138349 4.072578612124289e-09 0.06827606857536282" rpy="0 0 0" />
            <mass value="6.33360318547509" />
            <inertia ixx="0.02843678214118217" iyy="0.03981948777555333" izz="0.025134874646876526" ixy="-3.353012312246051e-12" iyz="4.741873560476506e-12" ixz="0.010596038306837752" />
        </inertial>
        <visual name="robot_r_hip_yaw_link_visual">
            <origin xyz="-0.0009999980926566998 4.0531109135599765e-09 0.12129999999999001" rpy="3.1415926535897802 0 0" />
            <geometry>
                <mesh filename="meshes/robot_r_hip_yaw_link.stl" scale="0.001 0.001 0.001" />
            </geometry>
        </visual>
        <collision name="robot_r_hip_yaw_link_collision">
            <origin xyz="-0.0009999980926566998 4.0531109135599765e-09 0.12129999999999001" rpy="3.1415926535897802 0 0" />
            <geometry>
                <mesh filename="meshes/robot_r_hip_yaw_link.stl" scale="0.001 0.001 0.001" />
            </geometry>
        </collision>
    </link>
    <link name="robot_r_hip_pitch_link">
        <inertial>
            <origin xyz="-0.026950748673872482 -4.88774409745929e-07 0.07268407470290482" rpy="0 0 0" />
            <mass value="2.4943200880759147" />
            <inertia ixx="0.005318838704479356" iyy="0.0035222338455168783" izz="0.003180296615424849" ixy="-2.273747284897709e-08" iyz="2.8234854454467495e-09" ixz="0.00011208276943740214" />
        </inertial>
        <visual name="robot_r_hip_pitch_link_visual">
            <origin xyz="0.0008000040530125752 -0.25730000000001313 0.07500000548354112" rpy="1.5707963267948843 -1.5707963267948957 0" />
            <geometry>
                <mesh filename="meshes/robot_r_hip_pitch_link.stl" scale="0.001 0.001 0.001" />
            </geometry>
        </visual>
        <collision name="robot_r_hip_pitch_link_collision">
            <origin xyz="0.0008000040530125752 -0.25730000000001313 0.07500000548354112" rpy="1.5707963267948843 -1.5707963267948957 0" />
            <geometry>
                <mesh filename="meshes/robot_r_hip_pitch_link.stl" scale="0.001 0.001 0.001" />
            </geometry>
        </collision>
    </link>
    <link name="robot_r_thigh_link">
        <inertial>
            <origin xyz="0.013245027463408991 0.0041376628277389575 0.25793145738807766" rpy="0 0 0" />
            <mass value="3.0917752218546957" />
            <inertia ixx="0.028832188657983426" iyy="0.026802665253455205" izz="0.0036078750192149595" ixy="0.00010068883404956708" iyz="0.002145417166664748" ixz="-0.0010188574476189816" />
        </inertial>
        <visual name="robot_r_thigh_link_visual">
            <origin xyz="0.0065000019073440645 -0.0004999959468891291 0" rpy="3.14159265358978 0 0" />
            <geometry>
                <mesh filename="meshes/robot_r_thigh_link.stl" scale="0.001 0.001 0.001" />
            </geometry>
        </visual>
        <collision name="robot_r_thigh_link_collision">
            <origin xyz="0.0065000019073440645 -0.0004999959468891291 0" rpy="3.14159265358978 0 0" />
            <geometry>
                <mesh filename="meshes/robot_r_thigh_link.stl" scale="0.001 0.001 0.001" />
            </geometry>
        </collision>
    </link>
    <link name="robot_r_shank_link">
        <inertial>
            <origin xyz="4.053073610066349e-09 -0.1499999999999902 0.020887098746808892" rpy="0 0 0" />
            <mass value="0.8515894596853654" />
            <inertia ixx="0.008817835807396313" iyy="0.00018545866885018997" izz="0.00888590939695276" ixy="1.3183898417423736e-16" iyz="-8.673617379884035e-17" ixz="-9.71445146547012e-17" />
        </inertial>
        <visual name="robot_r_shank_link_visual">
            <origin xyz="4.053111481994165e-09 0.30000000000001625 -0.021500001955065164" rpy="-1.570796326794883 -1.5707963267948895 0" />
            <geometry>
                <mesh filename="meshes/robot_r_shank_link.stl" scale="0.001 0.001 0.001" />
            </geometry>
        </visual>
        <collision name="robot_r_shank_link_collision">
            <origin xyz="4.053111481994165e-09 0.30000000000001625 -0.021500001955065164" rpy="-1.570796326794883 -1.5707963267948895 0" />
            <geometry>
                <mesh filename="meshes/robot_r_shank_link.stl" scale="0.001 0.001 0.001" />
            </geometry>
        </collision>
    </link>
    <link name="robot_r_ankle_link">
        <inertial>
            <origin xyz="0.0025096898970127057 -4.881742402496059e-07 -0.027692556251518372" rpy="0 0 0" />
            <mass value="2.4975426861194876" />
            <inertia ixx="0.0031700827310189514" iyy="0.003545876434914566" izz="0.005361501992920389" ixy="-3.0598998820852152e-09" iyz="-2.2441597559430537e-08" ixz="-8.723165997445714e-05" />
        </inertial>
        <visual name="robot_r_ankle_link_visual">
            <origin xyz="4.05311087803284e-09 0.6000000000000114 -0.01950000190734407" rpy="-1.5707963267949099 1.5707963267948957 0" />
            <geometry>
                <mesh filename="meshes/robot_r_ankle_link.stl" scale="0.001 0.001 0.001" />
            </geometry>
        </visual>
        <collision name="robot_r_ankle_link_collision">
            <origin xyz="4.05311087803284e-09 0.6000000000000114 -0.01950000190734407" rpy="-1.5707963267949099 1.5707963267948957 0" />
            <geometry>
                <mesh filename="meshes/robot_r_ankle_link.stl" scale="0.001 0.001 0.001" />
            </geometry>
        </collision>
    </link>
    <link name="robot_r_foot_link">
        <inertial>
            <origin xyz="1.699318552539353e-09 0.02129507460669811 0.009743852524875" rpy="0 0 0" />
            <mass value="2.7896715673151693" />
            <inertia ixx="0.007113124257631137" iyy="0.007089530917849758" izz="0.005986516165940273" ixy="-3.032198797603414e-11" iyz="0.0012082496450576182" ixz="3.797783962311563e-11" />
        </inertial>
        <visual name="robot_r_foot_link_visual">
            <origin xyz="0.009500001907344959 -0.07400000000000669 -0.6000000000000062" rpy="3.1415926535897802 0 0" />
            <geometry>
                <mesh filename="meshes/robot_r_foot_link.stl" scale="0.001 0.001 0.001" />
            </geometry>
        </visual>
        <collision name="robot_r_foot_link_collision">
            <origin xyz="0.009500001907344959 -0.07400000000000669 -0.6000000000000062" rpy="3.1415926535897802 0 0" />
            <geometry>
                <mesh filename="meshes/robot_r_foot_link.stl" scale="0.001 0.001 0.001" />
            </geometry>
        </collision>
    </link>
        <joint name="isaac_zup_root_joint" type="fixed">
        <parent link="isaac_zup_root" />
        <child link="robot_pelvis_link" />
        <origin xyz="0 0 0" rpy="1.57079632679 0 1.57079632679" />
    </joint>
    <joint name="robot_pelvis_link_torso_joint" type="fixed">
        <origin xyz="-0.03999999999999768 0.8247999999999912 -0.2065000040531073" rpy="-1.5707963267948837 0 0" />
        <parent link="robot_pelvis_link" />
        <child link="robot_torso_link" />
    </joint>
    <joint name="robot_pelvis_link_l_yaw_joint" type="revolute">
        <origin xyz="0.12000000000000183 0.8127999999999906 -0.16050000405310783" rpy="1.5707963267949094 0 0" />
        <parent link="robot_pelvis_link" />
        <child link="robot_l_hip_yaw_link" />
        <axis xyz="0 0 1.0" />
        <limit lower="-0.523599" upper="0.523599" effort="1000000" velocity="1000000" />
    </joint>
    <joint name="robot_pelvis_link_r_yaw_joint" type="revolute">
        <origin xyz="-0.11999999999999739 0.8127999999999906 -0.1605000040531078" rpy="1.5707963267949094 0 0" />
        <parent link="robot_pelvis_link" />
        <child link="robot_r_hip_yaw_link" />
        <axis xyz="0 0 -1.0" />
        <limit lower="-0.523599" upper="0.523599" effort="1000000" velocity="1000000" />
    </joint>
    <joint name="robot_l_hip_yaw_link_l_pitch_joint" type="revolute">
        <origin xyz="0.075 0 0.13629999999999995" rpy="1.5707963267948966 0 1.5707963267948966" />
        <parent link="robot_l_hip_yaw_link" />
        <child link="robot_l_hip_pitch_link" />
        <axis xyz="0 0 -1.0" />
        <limit lower="-0.698132" upper="1.047198" effort="1000000" velocity="1000000" />
    </joint>
    <joint name="robot_r_hip_yaw_link_r_pitch_joint" type="revolute">
        <origin xyz="-0.075 0 0.13629999999999995" rpy="1.5707963267948966 0 1.5707963267948966" />
        <parent link="robot_r_hip_yaw_link" />
        <child link="robot_r_hip_pitch_link" />
        <axis xyz="0 0 -1.0" />
        <limit lower="-0.698132" upper="1.047198" effort="1000000" velocity="1000000" />
    </joint>
    <joint name="robot_l_hip_pitch_link_l_roll_joint" type="revolute">
        <origin xyz="0.00048843999999999 -5.907999999990921e-05 -0.07498435" rpy="-1.5707963267948966 -1.5707963267948966 0" />
        <parent link="robot_l_hip_pitch_link" />
        <child link="robot_l_thigh_link" />
        <axis xyz="0 1.0 0" />
        <limit lower="-0.436332" upper="0.436332" effort="1000000" velocity="1000000" />
    </joint>
    <joint name="robot_r_hip_pitch_link_r_roll_joint" type="revolute">
        <origin xyz="0.0005000000000000072 0 0.075" rpy="-1.5707963267948966 -1.5707963267948966 0" />
        <parent link="robot_r_hip_pitch_link" />
        <child link="robot_r_thigh_link" />
        <axis xyz="0 -1.0 0" />
        <limit lower="-0.436332" upper="0.436332" effort="1000000" velocity="1000000" />
    </joint>
    <joint name="robot_l_thigh_link_l_knee_joint" type="revolute">
        <origin xyz="0.013000000000000008 -0.0004999999999999716 0.3" rpy="-1.5707963267948966 0 1.5707963267948966" />
        <parent link="robot_l_thigh_link" />
        <child link="robot_l_shank_link" />
        <axis xyz="0 0 -1.0" />
        <limit lower="0.0" upper="2.094395" effort="1000000" velocity="1000000" />
    </joint>
    <joint name="robot_r_thigh_link_r_knee_joint" type="revolute">
        <origin xyz="-0.013000000000000008 -0.0005000000000000072 0.3000000000000001" rpy="-1.5707963267948966 0 1.5707963267948966" />
        <parent link="robot_r_thigh_link" />
        <child link="robot_r_shank_link" />
        <axis xyz="0 0 -1.0" />
        <limit lower="0.0" upper="2.094395" effort="1000000" velocity="1000000" />
    </joint>
    <joint name="robot_l_shank_link_l_ankle_joint" type="revolute">
        <origin xyz="0 -0.3 0" rpy="0 0 0" />
        <parent link="robot_l_shank_link" />
        <child link="robot_l_ankle_link" />
        <axis xyz="0 0 1.0" />
        <limit lower="-0.610865" upper="0.610865" effort="1000000" velocity="1000000" />
    </joint>
    <joint name="robot_r_shank_link_r_ankle_joint" type="revolute">
        <origin xyz="0 -0.3 0" rpy="0 0 0" />
        <parent link="robot_r_shank_link" />
        <child link="robot_r_ankle_link" />
        <axis xyz="0 0 1.0" />
        <limit lower="-0.610865" upper="0.610865" effort="1000000" velocity="1000000" />
    </joint>
    <joint name="robot_l_ankle_link_l_foot_joint" type="revolute">
        <origin xyz="0.07401155999999999 -5.9079999999998025e-05 0.009015649999999998" rpy="1.5707963267948966 1.5707963267948966 0" />
        <parent link="robot_l_ankle_link" />
        <child link="robot_l_foot_link" />
        <axis xyz="0 1.0 0" />
        <limit lower="-0.261799" upper="0.261799" effort="1000000" velocity="1000000" />
    </joint>
    <joint name="robot_r_ankle_link_r_foot_joint" type="revolute">
        <origin xyz="0.07400000000000001 0 -0.009000000000000005" rpy="1.5707963267948966 1.5707963267948966 0" />
        <parent link="robot_r_ankle_link" />
        <child link="robot_r_foot_link" />
        <axis xyz="0 -1.0 0" />
        <limit lower="-0.261799" upper="0.261799" effort="1000000" velocity="1000000" />
    </joint>
</robot>